<?xml version="1.0"?>
<robot name="ackermann_car">

  <!-- ===================== -->
  <!-- Base link / chassis    -->
  <!-- ===================== -->
  <link name="base_link">
    <inertial>
      <origin xyz="0 0 0.15" rpy="0 0 0"/>
      <mass value="5.0"/>
      <inertia ixx="0.2" ixy="0" ixz="0" iyy="0.2" iyz="0" izz="0.2"/>
    </inertial>

    <visual>
      <origin xyz="0 0 0.15" rpy="0 0 0"/>
      <geometry><box size="0.6 0.35 0.15"/></geometry>
    </visual>

    <collision>
      <origin xyz="0 0 0.15" rpy="0 0 0"/>
      <geometry><box size="0.6 0.35 0.15"/></geometry>
    </collision>
  </link>

  <!-- ===================== -->
  <!-- Steering knuckle links -->
  <!-- ===================== -->
  <link name="steer_fl_link">
    <inertial>
      <mass value="0.05"/>
      <inertia ixx="0.0001" ixy="0" ixz="0" iyy="0.0001" iyz="0" izz="0.0001"/>
    </inertial>
    <visual>
      <origin xyz="0 0 0" rpy="0 0 0"/>
      <geometry><box size="0.02 0.02 0.02"/></geometry>
    </visual>
    <collision>
      <origin xyz="0 0 0" rpy="0 0 0"/>
      <geometry><box size="0.02 0.02 0.02"/></geometry>
    </collision>
  </link>

  <link name="steer_fr_link">
    <inertial>
      <mass value="0.05"/>
      <inertia ixx="0.0001" ixy="0" ixz="0" iyy="0.0001" iyz="0" izz="0.0001"/>
    </inertial>
    <visual>
      <origin xyz="0 0 0" rpy="0 0 0"/>
      <geometry><box size="0.02 0.02 0.02"/></geometry>
    </visual>
    <collision>
      <origin xyz="0 0 0" rpy="0 0 0"/>
      <geometry><box size="0.02 0.02 0.02"/></geometry>
    </collision>
  </link>

  <!-- ===================== -->
  <!-- Wheel links            -->
  <!-- ===================== -->
  <link name="wheel_rl_link">
    <inertial>
      <mass value="0.2"/>
      <inertia ixx="0.001" ixy="0" ixz="0" iyy="0.001" iyz="0" izz="0.001"/>
    </inertial>
    <visual>
      <origin xyz="0 0 0" rpy="0 1.5708 0"/>
      <geometry><cylinder radius="0.06" length="0.04"/></geometry>
    </visual>
    <collision>
      <origin xyz="0 0 0" rpy="0 1.5708 0"/>
      <geometry><cylinder radius="0.06" length="0.04"/></geometry>
    </collision>
  </link>

  <link name="wheel_rr_link">
    <inertial>
      <mass value="0.2"/>
      <inertia ixx="0.001" ixy="0" ixz="0" iyy="0.001" iyz="0" izz="0.001"/>
    </inertial>
    <visual>
      <origin xyz="0 0 0" rpy="0 1.5708 0"/>
      <geometry><cylinder radius="0.06" length="0.04"/></geometry>
    </visual>
    <collision>
      <origin xyz="0 0 0" rpy="0 1.5708 0"/>
      <geometry><cylinder radius="0.06" length="0.04"/></geometry>
    </collision>
  </link>

  <link name="wheel_fl_link">
    <inertial>
      <mass value="0.2"/>
      <inertia ixx="0.001" ixy="0" ixz="0" iyy="0.001" iyz="0" izz="0.001"/>
    </inertial>
    <visual>
      <origin xyz="0 0 0" rpy="0 1.5708 0"/>
      <geometry><cylinder radius="0.06" length="0.04"/></geometry>
    </visual>
    <collision>
      <origin xyz="0 0 0" rpy="0 1.5708 0"/>
      <geometry><cylinder radius="0.06" length="0.04"/></geometry>
    </collision>
  </link>

  <link name="wheel_fr_link">
    <inertial>
      <mass value="0.2"/>
      <inertia ixx="0.001" ixy="0" ixz="0" iyy="0.001" iyz="0" izz="0.001"/>
    </inertial>
    <visual>
      <origin xyz="0 0 0" rpy="0 1.5708 0"/>
      <geometry><cylinder radius="0.06" length="0.04"/></geometry>
    </visual>
    <collision>
      <origin xyz="0 0 0" rpy="0 1.5708 0"/>
      <geometry><cylinder radius="0.06" length="0.04"/></geometry>
    </collision>
  </link>

  <!-- ===================== -->
  <!-- Joints                 -->
  <!-- ===================== -->

  <!-- Rear wheel spin joints -->
  <joint name="rear_left_wheel_joint" type="continuous">
    <parent link="base_link"/>
    <child link="wheel_rl_link"/>
    <origin xyz="-0.20  0.17 0.08" rpy="0 0 0"/>
    <axis xyz="0 1 0"/>
  </joint>

  <joint name="rear_right_wheel_joint" type="continuous">
    <parent link="base_link"/>
    <child link="wheel_rr_link"/>
    <origin xyz="-0.20 -0.17 0.08" rpy="0 0 0"/>
    <axis xyz="0 1 0"/>
  </joint>

  <!-- Front steering joints -->
  <joint name="front_left_steer_joint" type="revolute">
    <parent link="base_link"/>
    <child link="steer_fl_link"/>
    <origin xyz="0.25  0.17 0.08" rpy="0 0 0"/>
    <axis xyz="0 0 1"/>
    <limit lower="-0.6" upper="0.6" effort="20" velocity="2.0"/>
  </joint>

  <joint name="front_right_steer_joint" type="revolute">
    <parent link="base_link"/>
    <child link="steer_fr_link"/>
    <origin xyz="0.25 -0.17 0.08" rpy="0 0 0"/>
    <axis xyz="0 0 1"/>
    <limit lower="-0.6" upper="0.6" effort="20" velocity="2.0"/>
  </joint>

  <!-- Front wheel spin joints -->
  <joint name="front_left_wheel_joint" type="continuous">
    <parent link="steer_fl_link"/>
    <child link="wheel_fl_link"/>
    <origin xyz="0 0 0" rpy="0 0 0"/>
    <axis xyz="0 1 0"/>
  </joint>

  <joint name="front_right_wheel_joint" type="continuous">
    <parent link="steer_fr_link"/>
    <child link="wheel_fr_link"/>
    <origin xyz="0 0 0" rpy="0 0 0"/>
    <axis xyz="0 1 0"/>
  </joint>

  <!-- ===================== -->
  <!-- Transmissions (ros_control) -->
  <transmission name="tran_rear_left">
    <type>transmission_interface/SimpleTransmission</type>
    <joint name="rear_left_wheel_joint">
      <hardwareInterface>hardware_interface/EffortJointInterface</hardwareInterface>
    </joint>
    <actuator name="rear_left_motor">
      <hardwareInterface>hardware_interface/EffortJointInterface</hardwareInterface>
      <mechanicalReduction>1</mechanicalReduction>
    </actuator>
  </transmission>

  <transmission name="tran_rear_right">
    <type>transmission_interface/SimpleTransmission</type>
    <joint name="rear_right_wheel_joint">
      <hardwareInterface>hardware_interface/EffortJointInterface</hardwareInterface>
    </joint>
    <actuator name="rear_right_motor">
      <hardwareInterface>hardware_interface/EffortJointInterface</hardwareInterface>
      <mechanicalReduction>1</mechanicalReduction>
    </actuator>
  
  </transmission>
  <!-- ===================== -->

  <transmission name="tran_rear_left">
    <type>transmission_interface/SimpleTransmission</type>
    <joint name="rear_left_wheel_joint">
      <hardwareInterface>hardware_interface/VelocityJointInterface</hardwareInterface>
    </joint>
    <actuator name="rear_left_motor">
      <hardwareInterface>hardware_interface/VelocityJointInterface</hardwareInterface>
      <mechanicalReduction>1</mechanicalReduction>
    </actuator>
  </transmission>

  <transmission name="tran_rear_right">
    <type>transmission_interface/SimpleTransmission</type>
    <joint name="rear_right_wheel_joint">
      <hardwareInterface>hardware_interface/VelocityJointInterface</hardwareInterface>
    </joint>
    <actuator name="rear_right_motor">
      <hardwareInterface>hardware_interface/VelocityJointInterface</hardwareInterface>
      <mechanicalReduction>1</mechanicalReduction>
    </actuator>
  </transmission>

  <transmission name="tran_front_left_steer">
    <type>transmission_interface/SimpleTransmission</type>
    <joint name="front_left_steer_joint">
      <hardwareInterface>hardware_interface/PositionJointInterface</hardwareInterface>
    </joint>
    <actuator name="front_left_steer_motor">
      <hardwareInterface>hardware_interface/PositionJointInterface</hardwareInterface>
      <mechanicalReduction>1</mechanicalReduction>
    </actuator>
  </transmission>

  <transmission name="tran_front_right_steer">
    <type>transmission_interface/SimpleTransmission</type>
    <joint name="front_right_steer_joint">
      <hardwareInterface>hardware_interface/PositionJointInterface</hardwareInterface>
    </joint>
    <actuator name="front_right_steer_motor">
      <hardwareInterface>hardware_interface/PositionJointInterface</hardwareInterface>
      <mechanicalReduction>1</mechanicalReduction>
    </actuator>
  </transmission>

  <!-- ===================== -->
  <!-- Gazebo friction hints   -->
  <!-- ===================== -->
  <gazebo reference="base_link">
    <mu1>1.0</mu1>
    <mu2>1.0</mu2>
  </gazebo>

  <!-- ===================== -->
  <!-- Gazebo ros_control      -->
  <!-- IMPORTANT: this makes controller_manager appear -->
  <!-- ===================== -->
  <gazebo>
    <plugin name="gazebo_ros_control" filename="libgazebo_ros_control.so">
      <robotNamespace>/ackermann_car</robotNamespace>
    </plugin>
  </gazebo>

</robot>
